File: .ipynb_checkpoints/POL_Tracao_GLR_2-checkpoint.csv
Position (mm);Force (N);Strain (%);Time (min)
0,00;0,00;-0,00167;0,00321
0,0271;3,33;0,00536;0,00872
0,0551;6,67;0,0124;0,0142
0,0826;10,0;0,0189;0,0197
0,110;13,3;0,0255;0,0253
0,138;15,0;0,0320;0,0308
0,165;18,3;0,0385;0,0363
0,192;20,0;0,0451;0,0418
0,220;23,3;0,0517;0,0473
0,248;26,4;0,0586;0,0528
0,275;28,3;0,0654;0,0583
0,303;31,7;0,0725;0,0639
0,331;35,0;0,0798;0,0694
0,358;38,3;0,0872;0,0749
0,386;40,0;0,0948;0,0804
0,414;43,3;0,103;0,0859
0,441;46,7;0,111;0,0914
0,469;50,0;0,119;0,0969
0,496;53,2;0,127;0,102
0,524;56,7;0,135;0,108
0,551;60,0;0,144;0,113
0,579;62,7;0,154;0,119
0,607;66,7;0,163;0,125
0,634;70,0;0,173;0,130
0,661;73,3;0,184;0,136
0,689;76,7;0,194;0,141
0,716;81,7;0,205;0,147
0,744;85,0;0,216;0,152
0,772;88,3;0,227;0,158
0,800;92,3;0,239;0,163
0,827;96,7;0,251;0,169
0,855;100;0,263;0,174
0,883;103;0,275;0,180
0,909;107;0,288;0,185
0,937;112;0,301;0,191
0,965;115;0,314;0,196
0,992;120;0,327;0,202
1,02;123;0,340;0,207
1,05;127;0,354;0,213
1,07;132;0,368;0,218
1,10;135;0,382;0,224
1,13;139;0,396;0,229
1,16;143;0,411;0,235
1,19;147;0,425;0,240
1,21;152;0,440;0,246
1,24;155;0,455;0,251
1,27;160;0,471;0,257
1,30;163;0,486;0,262
1,32;168;0,501;0,268
1,35;172;0,516;0,273
1,38;175;0,532;0,279
1,41;179;0,548;0,284
1,43;183;0,564;0,290
1,46;188;0,580;0,295
1,49;192;0,597;0,301
1,52;197;0,613;0,306
1,54;200;0,630;0,312
1,57;204;0,646;0,318
1,60;207;0,663;0,323
1,63;212;0,680;0,329
1,65;215;0,697;0,334
1,68;219;0,714;0,340
1,71;223;0,732;0,345
1,74;227;0,750;0,351
1,76;230;0,767;0,356
1,82;238;0,801;0,367
1,82;238;0,801;0,367
1,85;242;0,801;0,373
1,88;247;0,801;0,379
1,91;250;0,801;0,385
1,93;255;0,801;0,390
1,96;258;0,801;0,396
1,99;262;0,801;0,402
2,02;265;0,801;0,408
2,05;270;0,801;0,413
2,08;273;0,801;0,419
2,11;277;0,801;0,425
2,14;280;0,801;0,431
2,17;283;0,801;0,437
2,20;288;0,801;0,442
2,22;292;0,801;0,448
2,25;295;0,801;0,454
2,28;299;0,801;0,460
2,31;302;0,801;0,466
2,34;305;0,801;0,471
2,37;308;0,801;0,477
2,40;312;0,801;0,483
2,43;316;0,801;0,489
2,46;318;0,801;0,494
2,48;322;0,801;0,500
2,51;326;0,801;0,506
2,54;330;0,801;0,512
2,57;332;0,801;0,518
2,60;337;0,801;0,523
2,63;341;0,801;0,529
2,66;343;0,801;0,535
2,69;347;0,801;0,541
2,72;350;0,801;0,547
2,74;353;0,801;0,552
2,77;357;0,801;0,558
2,80;360;0,801;0,564
2,83;362;0,801;0,570
2,86;365;0,801;0,575
2,89;368;0,801;0,581
2,92;372;0,801;0,587
2,95;375;0,801;0,593
2,98;377;0,801;0,599
3,01;380;0,801;0,604
3,03;385;0,801;0,610
3,06;387;0,801;0,616
3,09;389;0,801;0,622
3,12;392;0,801;0,628
3,15;395;0,801;0,633
3,18;398;0,801;0,639
3,21;400;0,801;0,645
3,24;403;0,801;0,651
3,27;407;0,801;0,656
3,29;408;0,801;0,662
3,32;412;0,801;0,668
3,35;415;0,801;0,674
3,38;417;0,801;0,680
3,41;420;0,801;0,685
3,44;422;0,801;0,691
3,47;425;0,801;0,697
3,50;427;0,801;0,703
3,53;430;0,801;0,709
3,56;433;0,801;0,714
3,58;435;0,801;0,720
3,61;437;0,801;0,726
3,64;440;0,801;0,732
3,67;442;0,801;0,737
3,70;445;0,801;0,743
3,73;447;0,801;0,749
3,76;450;0,801;0,755
3,79;452;0,801;0,761
3,82;455;0,801;0,766
3,84;457;0,801;0,772
3,87;458;0,801;0,778
3,90;460;0,801;0,784
3,93;463;0,801;0,790
3,96;465;0,801;0,795
3,99;468;0,801;0,801
4,02;470;0,801;0,807
4,05;473;0,801;0,813
4,10;477;0,801;0,824
4,10;477;0,801;0,824
4,52;561;0,801;0,834
5,00;620;0,801;0,843
5,46;661;0,801;0,852
5,94;695;0,801;0,862
6,41;721;0,801;0,871
6,88;742;0,801;0,881
7,34;760;0,801;0,890
7,81;773;0,801;0,899
8,28;786;0,801;0,909
8,76;795;0,801;0,918
9,23;803;0,801;0,928
9,70;808;0,801;0,937
10,2;813;0,801;0,946
10,6;817;0,801;0,956
11,1;820;0,801;0,965
11,6;820;0,801;0,975
12,0;822;0,801;0,984
12,5;822;0,801;0,993
13,0;821;0,801;1,00
13,5;820;0,801;1,01
13,9;818;0,801;1,02
14,4;817;0,801;1,03
14,9;815;0,801;1,04
15,3;813;0,801;1,05
15,8;810;0,801;1,06
16,3;808;0,801;1,07
16,7;805;0,801;1,08
17,2;802;0,801;1,09
17,7;798;0,801;1,10
18,2;795;0,801;1,11
18,6;792;0,801;1,12
19,1;788;0,801;1,13
19,6;785;0,801;1,13
20,0;783;0,801;1,14
20,5;778;0,801;1,15
21,0;775;0,801;1,16
21,4;772;0,801;1,17
21,9;767;0,801;1,18
22,4;763;0,801;1,19
22,9;760;0,801;1,20
23,3;757;0,801;1,21
23,8;753;0,801;1,22
24,3;750;0,801;1,23
24,7;745;0,801;1,24
25,2;742;0,801;1,25
25,7;738;0,801;1,26
26,1;733;0,801;1,27
26,6;730;0,801;1,28
27,1;727;0,801;1,28
27,6;723;0,801;1,29
28,0;718;0,801;1,30
28,5;715;0,801;1,31
29,0;712;0,801;1,32
29,4;707;0,801;1,33
29,9;703;0,801;1,34
30,4;700;0,801;1,35
30,8;695;0,801;1,36
31,3;692;0,801;1,37
31,8;688;0,801;1,38
32,3;683;0,801;1,39
32,7;680;0,801;1,40
33,2;675;0,801;1,41
33,7;670;0,801;1,42
34,1;665;0,801;1,43
34,6;662;0,801;1,44
35,1;657;0,801;1,44
35,5;650;0,801;1,45
36,0;645;0,801;1,46
36,5;639;0,801;1,47
37,0;633;0,801;1,48
37,4;625;0,801;1,49
37,9;618;0,801;1,50
38,4;610;0,801;1,51
38,8;598;0,801;1,52
39,3;587;0,801;1,53
39,8;573;0,801;1,54
40,2;556;0,801;1,55
40,7;538;0,801;1,56
41,2;517;0,801;1,57
41,7;496;0,801;1,58
42,1;477;0,801;1,59
42,6;463;0,801;1,59
43,1;453;0,801;1,60
43,5;448;0,801;1,61
44,0;445;0,801;1,62
44,5;443;0,801;1,63
44,9;442;0,801;1,64
45,4;440;0,801;1,65
45,9;440;0,801;1,66
46,4;440;0,801;1,67
46,8;440;0,801;1,68
47,3;440;0,801;1,69
47,8;440;0,801;1,70
48,2;440;0,801;1,71
48,7;440;0,801;1,72
49,2;440;0,801;1,73
49,6;440;0,801;1,74
50,1;440;0,801;1,75
50,6;440;0,801;1,75
51,1;440;0,801;1,76
51,5;440;0,801;1,77
52,0;440;0,801;1,78
52,5;442;0,801;1,79
52,9;442;0,801;1,80
53,4;442;0,801;1,81
53,9;442;0,801;1,82
54,3;442;0,801;1,83
54,8;442;0,801;1,84
55,3;442;0,801;1,85
55,8;443;0,801;1,86
56,2;443;0,801;1,87
56,7;443;0,801;1,88
57,2;443;0,801;1,89
57,6;443;0,801;1,90
58,1;443;0,801;1,91
58,6;443;0,801;1,91
59,0;443;0,801;1,92
59,5;443;0,801;1,93
60,0;443;0,801;1,94
60,5;443;0,801;1,95
60,9;443;0,801;1,96
61,4;443;0,801;1,97
61,9;443;0,801;1,98
62,3;445;0,801;1,99
62,8;445;0,801;2,00
63,3;445;0,801;2,01
63,7;445;0,801;2,02
64,2;445;0,801;2,03
64,7;445;0,801;2,04
65,2;445;0,801;2,05
65,6;445;0,801;2,06
66,1;445;0,801;2,06
66,6;447;0,801;2,07
67,0;447;0,801;2,08
67,5;447;0,801;2,09
68,0;448;0,801;2,10
68,4;448;0,801;2,11
68,9;448;0,801;2,12
69,4;448;0,801;2,13
69,9;448;0,801;2,14
70,3;448;0,801;2,15
70,8;448;0,801;2,16
71,3;450;0,801;2,17
71,7;450;0,801;2,18
72,2;450;0,801;2,19
72,7;450;0,801;2,20
73,1;450;0,801;2,21
73,6;450;0,801;2,22
74,1;450;0,801;2,22
74,6;450;0,801;2,23
75,0;450;0,801;2,24
75,5;450;0,801;2,25
76,0;450;0,801;2,26
76,4;449;0,801;2,27
76,9;450;0,801;2,28
77,4;450;0,801;2,29
77,8;450;0,801;2,30
78,3;450;0,801;2,31
78,8;450;0,801;2,32
79,2;450;0,801;2,33
79,7;450;0,801;2,34
80,2;450;0,801;2,35
80,7;451;0,801;2,36
81,1;451;0,801;2,37
81,6;452;0,801;2,38
82,1;452;0,801;2,38
82,5;452;0,801;2,39
83,0;452;0,801;2,40
83,5;452;0,801;2,41
83,9;452;0,801;2,42
84,4;452;0,801;2,43
84,9;452;0,801;2,44
85,4;452;0,801;2,45
85,8;452;0,801;2,46
86,3;452;0,801;2,47
86,8;452;0,801;2,48
87,2;452;0,801;2,49
87,7;453;0,801;2,50
88,2;453;0,801;2,51
88,6;453;0,801;2,52
89,1;453;0,801;2,53
89,6;453;0,801;2,53
90,1;453;0,801;2,54
90,5;453;0,801;2,55
91,0;453;0,801;2,56
91,5;455;0,801;2,57
91,9;455;0,801;2,58
92,4;455;0,801;2,59
92,9;455;0,801;2,60
93,3;455;0,801;2,61
93,8;455;0,801;2,62
94,3;455;0,801;2,63
94,8;455;0,801;2,64
95,2;455;0,801;2,65
95,7;455;0,801;2,66
96,2;455;0,801;2,67
96,6;456;0,801;2,68
97,1;455;0,801;2,69
97,6;457;0,801;2,69
98,0;457;0,801;2,70
98,5;457;0,801;2,71
99,0;457;0,801;2,72
99,5;458;0,801;2,73
99,9;458;0,801;2,74
100;458;0,801;2,75
101;459;0,801;2,76
101;458;0,801;2,77
102;460;0,801;2,78
102;460;0,801;2,79
103;460;0,801;2,80
103;460;0,801;2,81
104;460;0,801;2,82
104;460;0,801;2,83
105;460;0,801;2,84
105;460;0,801;2,85
106;460;0,801;2,85
106;460;0,801;2,86
107;460;0,801;2,87
107;460;0,801;2,88
107;460;0,801;2,89
108;460;0,801;2,90
108;460;0,801;2,91
109;460;0,801;2,92
109;460;0,801;2,93
110;460;0,801;2,94
110;460;0,801;2,95
111;460;0,801;2,96
111;460;0,801;2,97
112;460;0,801;2,98
112;460;0,801;2,99
113;460;0,801;3,00
113;460;0,801;3,00
114;460;0,801;3,01
114;460;0,801;3,02
114;462;0,801;3,03
115;461;0,801;3,04
115;460;0,801;3,05
116;460;0,801;3,06
116;460;0,801;3,07
117;460;0,801;3,08
117;460;0,801;3,09
118;460;0,801;3,10
118;460;0,801;3,11
119;460;0,801;3,12
119;460;0,801;3,13
120;460;0,801;3,14
120;460;0,801;3,15
121;460;0,801;3,16
121;460;0,801;3,16
122;460;0,801;3,17
122;460;0,801;3,18
122;460;0,801;3,19
123;460;0,801;3,20
123;460;0,801;3,21
124;460;0,801;3,22
124;460;0,801;3,23
125;460;0,801;3,24
125;460;0,801;3,25
126;462;0,801;3,26
126;462;0,801;3,27
127;462;0,801;3,28
127;462;0,801;3,29
128;462;0,801;3,30
128;462;0,801;3,31
129;462;0,801;3,32
129;462;0,801;3,32
130;462;0,801;3,33
130;462;0,801;3,34
130;462;0,801;3,35
131;462;0,801;3,36
131;462;0,801;3,37
132;462;0,801;3,38
132;462;0,801;3,39
133;463;0,801;3,40
133;462;0,801;3,41
134;462;0,801;3,42
134;462;0,801;3,43
135;462;0,801;3,44
135;462;0,801;3,45
136;462;0,801;3,46
136;462;0,801;3,47
137;462;0,801;3,47
137;462;0,801;3,48
138;462;0,801;3,49
138;462;0,801;3,50
138;463;0,801;3,51
139;462;0,801;3,52
139;462;0,801;3,53
140;462;0,801;3,54
140;462;0,801;3,55
141;462;0,801;3,56
141;462;0,801;3,57
142;462;0,801;3,58
142;462;0,801;3,59
143;462;0,801;3,60
143;463;0,801;3,61
144;463;0,801;3,62
144;463;0,801;3,63
145;463;0,801;3,63
145;463;0,801;3,64
146;463;0,801;3,65
146;463;0,801;3,66
146;462;0,801;3,67
147;462;0,801;3,68
147;462;0,801;3,69
148;463;0,801;3,70
148;463;0,801;3,71
149;463;0,801;3,72
149;463;0,801;3,73
150;463;0,801;3,74
150;463;0,801;3,75
151;463;0,801;3,76
151;463;0,801;3,77
152;463;0,801;3,78
152;463;0,801;3,78
153;463;0,801;3,79
153;463;0,801;3,80
154;463;0,801;3,81
154;463;0,801;3,82
154;463;0,801;3,83
155;463;0,801;3,84
155;463;0,801;3,85
156;463;0,801;3,86
156;463;0,801;3,87
157;465;0,801;3,88
157;465;0,801;3,89
158;465;0,801;3,90
158;465;0,801;3,91
159;465;0,801;3,92
159;465;0,801;3,93
160;465;0,801;3,94
160;467;0,801;3,94
161;467;0,801;3,95
161;467;0,801;3,96
161;467;0,801;3,97
162;467;0,801;3,98
162;467;0,801;3,99
163;467;0,801;4,00
163;467;0,801;4,01
164;467;0,801;4,02
164;467;0,801;4,03
165;467;0,801;4,04
165;467;0,801;4,05
166;467;0,801;4,06
166;467;0,801;4,07
167;467;0,801;4,08
167;467;0,801;4,09
168;467;0,801;4,10
168;467;0,801;4,10
169;467;0,801;4,11
169;467;0,801;4,12
169;467;0,801;4,13
170;467;0,801;4,14
170;467;0,801;4,15
171;467;0,801;4,16
171;467;0,801;4,17
172;467;0,801;4,18
172;468;0,801;4,19
173;468;0,801;4,20
173;468;0,801;4,21
174;468;0,801;4,22
174;469;0,801;4,23
175;468;0,801;4,24
175;468;0,801;4,25
176;468;0,801;4,25
176;468;0,801;4,26
177;468;0,801;4,27
177;468;0,801;4,28
177;468;0,801;4,29
178;468;0,801;4,30
178;468;0,801;4,31
179;470;0,801;4,32
179;468;0,801;4,33
180;468;0,801;4,34
180;468;0,801;4,35
181;468;0,801;4,36
181;468;0,801;4,37
182;468;0,801;4,38
182;468;0,801;4,39
183;468;0,801;4,40
183;468;0,801;4,41
184;468;0,801;4,41
184;468;0,801;4,42
185;468;0,801;4,43
185;468;0,801;4,44
185;468;0,801;4,45
186;468;0,801;4,46
186;468;0,801;4,47
187;468;0,801;4,48
187;468;0,801;4,49
188;468;0,801;4,50
188;468;0,801;4,51
189;468;0,801;4,52
189;470;0,801;4,53
190;470;0,801;4,54
190;470;0,801;4,55
191;469;0,801;4,56
191;469;0,801;4,57
192;470;0,801;4,57
192;468;0,801;4,58
193;470;0,801;4,59
193;470;0,801;4,60
193;470;0,801;4,61
194;472;0,801;4,62
194;470;0,801;4,63
195;472;0,801;4,64
195;472;0,801;4,65
196;472;0,801;4,66
196;470;0,801;4,67
197;472;0,801;4,68
197;472;0,801;4,69
198;472;0,801;4,70
198;472;0,801;4,71
199;472;0,801;4,72
199;472;0,801;4,72
200;472;0,801;4,73
200;472;0,801;4,74
200;472;0,801;4,75
201;472;0,801;4,76
201;472;0,801;4,77
202;472;0,801;4,78
202;472;0,801;4,79
203;472;0,801;4,80
203;472;0,801;4,81
204;473;0,801;4,82
204;472;0,801;4,83
205;472;0,801;4,84
205;472;0,801;4,85
206;473;0,801;4,86
206;472;0,801;4,87
207;472;0,801;4,88
207;472;0,801;4,88
208;472;0,801;4,89
208;473;0,801;4,90
208;473;0,801;4,91
209;475;0,801;4,92
209;473;0,801;4,93
210;473;0,801;4,94
210;473;0,801;4,95
211;472;0,801;4,96
211;473;0,801;4,97
212;473;0,801;4,98
212;473;0,801;4,99
213;473;0,801;5,00
213;472;0,801;5,01
214;472;0,801;5,02
214;472;0,801;5,03
215;472;0,801;5,04
215;472;0,801;5,04
216;472;0,801;5,05
216;473;0,801;5,06
216;473;0,801;5,07
217;473;0,801;5,08
217;473;0,801;5,09
218;473;0,801;5,10
218;473;0,801;5,11
219;473;0,801;5,12
219;473;0,801;5,13
220;473;0,801;5,14
220;473;0,801;5,15
221;473;0,801;5,16
221;473;0,801;5,17
222;473;0,801;5,18
222;473;0,801;5,19
223;473;0,801;5,19
223;473;0,801;5,20
224;473;0,801;5,21
224;473;0,801;5,22
224;473;0,801;5,23
225;473;0,801;5,24
225;473;0,801;5,25
226;475;0,801;5,26
226;474;0,801;5,27
227;474;0,801;5,28
227;473;0,801;5,29
228;473;0,801;5,30
228;475;0,801;5,31
229;475;0,801;5,32
229;475;0,801;5,33
230;475;0,801;5,34
230;475;0,801;5,35
231;474;0,801;5,35
231;475;0,801;5,36
232;475;0,801;5,37
232;475;0,801;5,38
232;475;0,801;5,39
233;475;0,801;5,40
233;475;0,801;5,41
234;475;0,801;5,42
234;475;0,801;5,43
235;475;0,801;5,44
235;475;0,801;5,45
236;475;0,801;5,46
236;475;0,801;5,47
237;475;0,801;5,48
237;475;0,801;5,49
238;475;0,801;5,50
238;475;0,801;5,51
239;477;0,801;5,51
239;477;0,801;5,52
240;477;0,801;5,53
240;477;0,801;5,54
240;476;0,801;5,55
241;476;0,801;5,56
241;477;0,801;5,57
242;477;0,801;5,58
242;477;0,801;5,59
243;477;0,801;5,60
243;477;0,801;5,61
244;477;0,801;5,62
244;478;0,801;5,63
245;478;0,801;5,64
245;478;0,801;5,65
246;478;0,801;5,66
246;478;0,801;5,66
247;478;0,801;5,67
247;478;0,801;5,68
247;478;0,801;5,69
248;478;0,801;5,70
248;478;0,801;5,71
249;478;0,801;5,72
249;480;0,801;5,73
250;480;0,801;5,74
250;480;0,801;5,75
251;480;0,801;5,76
251;480;0,801;5,77
252;480;0,801;5,78
252;480;0,801;5,79
253;480;0,801;5,80
253;480;0,801;5,81
254;478;0,801;5,82
254;479;0,801;5,82
255;478;0,801;5,83
255;478;0,801;5,84
255;478;0,801;5,85
256;478;0,801;5,86
256;478;0,801;5,87
257;478;0,801;5,88
257;478;0,801;5,89
258;480;0,801;5,90
258;480;0,801;5,91
259;480;0,801;5,92
259;478;0,801;5,93
260;478;0,801;5,94
260;478;0,801;5,95
261;478;0,801;5,96
261;478;0,801;5,97
262;478;0,801;5,97
262;478;0,801;5,98
263;478;0,801;5,99
263;478;0,801;6,00
263;478;0,801;6,01
264;477;0,801;6,02
264;477;0,801;6,03
265;477;0,801;6,04
265;477;0,801;6,05
266;477;0,801;6,06
266;478;0,801;6,07
267;478;0,801;6,08
267;478;0,801;6,09
268;478;0,801;6,10
268;477;0,801;6,11
269;477;0,801;6,12
269;477;0,801;6,13
270;477;0,801;6,13
270;477;0,801;6,14
271;477;0,801;6,15
271;478;0,801;6,16
271;478;0,801;6,17
272;477;0,801;6,18
272;477;0,801;6,19
273;477;0,801;6,20
273;477;0,801;6,21
274;477;0,801;6,22
274;477;0,801;6,23
275;477;0,801;6,24
275;477;0,801;6,25
276;477;0,801;6,26
276;477;0,801;6,27
277;477;0,801;6,28
277;477;0,801;6,29
278;477;0,801;6,29
278;477;0,801;6,30
279;477;0,801;6,31
279;477;0,801;6,32
279;477;0,801;6,33
280;477;0,801;6,34
280;476;0,801;6,35
281;477;0,801;6,36
281;477;0,801;6,37
282;477;0,801;6,38
282;477;0,801;6,39
283;477;0,801;6,40
283;477;0,801;6,41
284;477;0,801;6,42
284;477;0,801;6,43
285;477;0,801;6,44
285;477;0,801;6,44
286;477;0,801;6,45
286;477;0,801;6,46
287;477;0,801;6,47
287;477;0,801;6,48
287;476;0,801;6,49
288;477;0,801;6,50
288;477;0,801;6,51
289;477;0,801;6,52
289;477;0,801;6,53
290;477;0,801;6,54
290;477;0,801;6,55
291;477;0,801;6,56
291;477;0,801;6,57
292;477;0,801;6,58
292;477;0,801;6,59
293;477;0,801;6,60
293;477;0,801;6,60
294;477;0,801;6,61
294;477;0,801;6,62
294;477;0,801;6,63
295;477;0,801;6,64
295;477;0,801;6,65
296;475;0,801;6,66
296;475;0,801;6,67
297;475;0,801;6,68
297;475;0,801;6,69
298;475;0,801;6,70
298;476;0,801;6,71
299;475;0,801;6,72
299;477;0,801;6,73
300;477;0,801;6,74
300;475;0,801;6,75
301;475;0,801;6,76
301;475;0,801;6,76
302;475;0,801;6,77
302;477;0,801;6,78
302;477;0,801;6,79
303;476;0,801;6,80
303;477;0,801;6,81
304;477;0,801;6,82
304;477;0,801;6,83
305;477;0,801;6,84
305;477;0,801;6,85
306;477;0,801;6,86
306;477;0,801;6,87
307;477;0,801;6,88
307;477;0,801;6,89
308;478;0,801;6,90
308;478;0,801;6,91
309;478;0,801;6,91
309;478;0,801;6,92
310;478;0,801;6,93
310;478;0,801;6,94
310;477;0,801;6,95
311;477;0,801;6,96
311;477;0,801;6,97
312;477;0,801;6,98
312;477;0,801;6,99
313;477;0,801;7,00
313;477;0,801;7,01
314;477;0,801;7,02
314;477;0,801;7,03
315;477;0,801;7,04
315;477;0,801;7,05
316;477;0,801;7,06
316;477;0,801;7,07
317;477;0,801;7,07
317;477;0,801;7,08
318;477;0,801;7,09
318;477;0,801;7,10
318;477;0,801;7,11
319;477;0,801;7,12
319;478;0,801;7,13
320;477;0,801;7,14
320;477;0,801;7,15
321;477;0,801;7,16
321;477;0,801;7,17
322;478;0,801;7,18
322;478;0,801;7,19
323;478;0,801;7,20
323;478;0,801;7,21
324;478;0,801;7,22
324;478;0,801;7,23
325;478;0,801;7,23
325;478;0,801;7,24
326;478;0,801;7,25
326;478;0,801;7,26
326;478;0,801;7,27
327;478;0,801;7,28
327;478;0,801;7,29
328;478;0,801;7,30
328;478;0,801;7,31
329;478;0,801;7,32
329;478;0,801;7,33
330;478;0,801;7,34
330;478;0,801;7,35
331;479;0,801;7,36
331;478;0,801;7,37
332;480;0,801;7,38
332;480;0,801;7,38
333;478;0,801;7,39
333;479;0,801;7,40
333;478;0,801;7,41
334;479;0,801;7,42
334;480;0,801;7,43
335;480;0,801;7,44
335;478;0,801;7,45
336;479;0,801;7,46
336;478;0,801;7,47
337;478;0,801;7,48
337;478;0,801;7,49
338;480;0,801;7,50
338;480;0,801;7,51
339;480;0,801;7,52
339;480;0,801;7,53
340;480;0,801;7,54
340;478;0,801;7,54
341;478;0,801;7,55
341;478;0,801;7,56
341;478;0,801;7,57
342;478;0,801;7,58
342;480;0,801;7,59
343;479;0,801;7,60
343;480;0,801;7,61
344;480;0,801;7,62
344;480;0,801;7,63
345;480;0,801;7,64
345;480;0,801;7,65
346;481;0,801;7,66
346;482;0,801;7,67
347;482;0,801;7,68
347;482;0,801;7,69
348;482;0,801;7,70
348;482;0,801;7,70
349;482;0,801;7,71
349;482;0,801;7,72
349;482;0,801;7,73
350;482;0,801;7,74
350;482;0,801;7,75
351;482;0,801;7,76
351;483;0,801;7,77
352;482;0,801;7,78
352;482;0,801;7,79
353;483;0,801;7,80
353;482;0,801;7,81
354;482;0,801;7,82
354;482;0,801;7,83
355;482;0,801;7,84
355;482;0,801;7,85
356;482;0,801;7,85
356;482;0,801;7,86
357;483;0,801;7,87
357;482;0,801;7,88
357;482;0,801;7,89
358;482;0,801;7,90
358;482;0,801;7,91
359;482;0,801;7,92
359;482;0,801;7,93
360;482;0,801;7,94
360;482;0,801;7,95
361;481;0,801;7,96
361;482;0,801;7,97
362;482;0,801;7,98
362;482;0,801;7,99
363;482;0,801;8,00
363;483;0,801;8,01
364;483;0,801;8,01
364;483;0,801;8,02
365;483;0,801;8,03
365;483;0,801;8,04
365;483;0,801;8,05
366;483;0,801;8,06
366;482;0,801;8,07
367;482;0,801;8,08
367;482;0,801;8,09
368;483;0,801;8,10
368;483;0,801;8,11
369;483;0,801;8,12
369;483;0,801;8,13
370;483;0,801;8,14
370;483;0,801;8,15
371;483;0,801;8,16
371;483;0,801;8,17
372;483;0,801;8,17
372;483;0,801;8,18
373;483;0,801;8,19
373;483;0,801;8,20
373;483;0,801;8,21
374;483;0,801;8,22
374;483;0,801;8,23
375;483;0,801;8,24
375;483;0,801;8,25
376;483;0,801;8,26
376;485;0,801;8,27
377;485;0,801;8,28
377;484;0,801;8,29
378;485;0,801;8,30
378;483;0,801;8,31
379;485;0,801;8,32
379;485;0,801;8,32
380;485;0,801;8,33
380;485;0,801;8,34
380;485;0,801;8,35
381;485;0,801;8,36
381;485;0,801;8,37
382;485;0,801;8,38
382;485;0,801;8,39
383;485;0,801;8,40
383;485;0,801;8,41
384;485;0,801;8,42
384;485;0,801;8,43
385;485;0,801;8,44
385;485;0,801;8,45
386;485;0,801;8,46
386;487;0,801;8,47
387;487;0,801;8,48
387;487;0,801;8,48
388;487;0,801;8,49
388;487;0,801;8,50
388;488;0,801;8,51
389;488;0,801;8,52
389;488;0,801;8,53
390;488;0,801;8,54
390;488;0,801;8,55
391;488;0,801;8,56
391;488;0,801;8,57
392;488;0,801;8,58
392;488;0,801;8,59
393;488;0,801;8,60
393;488;0,801;8,61
394;488;0,801;8,62
394;488;0,801;8,63
395;490;0,801;8,63
395;490;0,801;8,64
396;490;0,801;8,65
396;490;0,801;8,66
396;490;0,801;8,67
397;490;0,801;8,68
397;490;0,801;8,69
398;490;0,801;8,70
398;490;0,801;8,71
399;491;0,801;8,72
399;491;0,801;8,73
400;490;0,801;8,74
400;488;0,801;8,75
401;487;0,801;8,76
401;485;0,801;8,77
402;485;0,801;8,78
402;485;0,801;8,79
403;487;0,801;8,79
403;485;0,801;8,80
404;483;0,801;8,81
404;485;0,801;8,82
404;485;0,801;8,83
405;479;0,801;8,84
406;5,00;0,801;8,86